{
 "cells": [
  {
   "cell_type": "markdown",
   "id": "b85fb6c0-416d-4310-b11e-e4ec7528890c",
   "metadata": {},
   "source": [
    "# 텔레그램 봇"
   ]
  },
  {
   "cell_type": "code",
   "execution_count": null,
   "id": "e54dca82-5d56-44f2-b1f2-b31b484fd240",
   "metadata": {},
   "outputs": [],
   "source": [
    "!pip install python-telegram-bot"
   ]
  },
  {
   "cell_type": "code",
   "execution_count": 1,
   "id": "c96d15d1-2b79-43ff-8ef1-4b8804e11bfd",
   "metadata": {},
   "outputs": [
    {
     "name": "stdout",
     "output_type": "stream",
     "text": [
      "봇이 실행중 입니다.\n"
     ]
    },
    {
     "name": "stderr",
     "output_type": "stream",
     "text": [
      "Exception happened while polling for updates.\n",
      "Traceback (most recent call last):\n",
      "  File \"C:\\Dev\\Lang\\Python313\\Lib\\site-packages\\telegram\\ext\\_updater.py\", line 750, in _network_loop_retry\n",
      "    if not await do_action():\n",
      "           ^^^^^^^^^^^^^^^^^\n",
      "  File \"C:\\Dev\\Lang\\Python313\\Lib\\site-packages\\telegram\\ext\\_updater.py\", line 744, in do_action\n",
      "    return action_cb_task.result()\n",
      "           ~~~~~~~~~~~~~~~~~~~~~^^\n",
      "  File \"C:\\Dev\\Lang\\Python313\\Lib\\asyncio\\futures.py\", line 199, in result\n",
      "    raise self._exception.with_traceback(self._exception_tb)\n",
      "  File \"C:\\Dev\\Lang\\Python313\\Lib\\asyncio\\tasks.py\", line 304, in __step_run_and_handle_result\n",
      "    result = coro.send(None)\n",
      "  File \"C:\\Dev\\Lang\\Python313\\Lib\\site-packages\\telegram\\ext\\_updater.py\", line 371, in polling_action_cb\n",
      "    updates = await self.bot.get_updates(\n",
      "              ^^^^^^^^^^^^^^^^^^^^^^^^^^^\n",
      "    ...<7 lines>...\n",
      "    )\n",
      "    ^\n",
      "  File \"C:\\Dev\\Lang\\Python313\\Lib\\site-packages\\telegram\\ext\\_extbot.py\", line 650, in get_updates\n",
      "    updates = await super().get_updates(\n",
      "              ^^^^^^^^^^^^^^^^^^^^^^^^^^\n",
      "    ...<9 lines>...\n",
      "    )\n",
      "    ^\n",
      "  File \"C:\\Dev\\Lang\\Python313\\Lib\\site-packages\\telegram\\_bot.py\", line 4480, in get_updates\n",
      "    await self._post(\n",
      "    ^^^^^^^^^^^^^^^^^\n",
      "    ...<7 lines>...\n",
      "    ),\n",
      "    ^\n",
      "  File \"C:\\Dev\\Lang\\Python313\\Lib\\site-packages\\telegram\\_bot.py\", line 619, in _post\n",
      "    return await self._do_post(\n",
      "           ^^^^^^^^^^^^^^^^^^^^\n",
      "    ...<6 lines>...\n",
      "    )\n",
      "    ^\n",
      "  File \"C:\\Dev\\Lang\\Python313\\Lib\\site-packages\\telegram\\ext\\_extbot.py\", line 354, in _do_post\n",
      "    return await super()._do_post(\n",
      "           ^^^^^^^^^^^^^^^^^^^^^^^\n",
      "    ...<6 lines>...\n",
      "    )\n",
      "    ^\n",
      "  File \"C:\\Dev\\Lang\\Python313\\Lib\\site-packages\\telegram\\_bot.py\", line 648, in _do_post\n",
      "    result = await request.post(\n",
      "             ^^^^^^^^^^^^^^^^^^^\n",
      "    ...<6 lines>...\n",
      "    )\n",
      "    ^\n",
      "  File \"C:\\Dev\\Lang\\Python313\\Lib\\site-packages\\telegram\\request\\_baserequest.py\", line 202, in post\n",
      "    result = await self._request_wrapper(\n",
      "             ^^^^^^^^^^^^^^^^^^^^^^^^^^^^\n",
      "    ...<7 lines>...\n",
      "    )\n",
      "    ^\n",
      "  File \"C:\\Dev\\Lang\\Python313\\Lib\\site-packages\\telegram\\request\\_baserequest.py\", line 385, in _request_wrapper\n",
      "    raise Conflict(message)\n",
      "telegram.error.Conflict: Conflict: terminated by other getUpdates request; make sure that only one bot instance is running\n",
      "Exception happened while polling for updates.\n",
      "Traceback (most recent call last):\n",
      "  File \"C:\\Dev\\Lang\\Python313\\Lib\\site-packages\\telegram\\ext\\_updater.py\", line 750, in _network_loop_retry\n",
      "    if not await do_action():\n",
      "           ^^^^^^^^^^^^^^^^^\n",
      "  File \"C:\\Dev\\Lang\\Python313\\Lib\\site-packages\\telegram\\ext\\_updater.py\", line 744, in do_action\n",
      "    return action_cb_task.result()\n",
      "           ~~~~~~~~~~~~~~~~~~~~~^^\n",
      "  File \"C:\\Dev\\Lang\\Python313\\Lib\\asyncio\\futures.py\", line 199, in result\n",
      "    raise self._exception.with_traceback(self._exception_tb)\n",
      "  File \"C:\\Dev\\Lang\\Python313\\Lib\\asyncio\\tasks.py\", line 304, in __step_run_and_handle_result\n",
      "    result = coro.send(None)\n",
      "  File \"C:\\Dev\\Lang\\Python313\\Lib\\site-packages\\telegram\\ext\\_updater.py\", line 371, in polling_action_cb\n",
      "    updates = await self.bot.get_updates(\n",
      "              ^^^^^^^^^^^^^^^^^^^^^^^^^^^\n",
      "    ...<7 lines>...\n",
      "    )\n",
      "    ^\n",
      "  File \"C:\\Dev\\Lang\\Python313\\Lib\\site-packages\\telegram\\ext\\_extbot.py\", line 650, in get_updates\n",
      "    updates = await super().get_updates(\n",
      "              ^^^^^^^^^^^^^^^^^^^^^^^^^^\n",
      "    ...<9 lines>...\n",
      "    )\n",
      "    ^\n",
      "  File \"C:\\Dev\\Lang\\Python313\\Lib\\site-packages\\telegram\\_bot.py\", line 4480, in get_updates\n",
      "    await self._post(\n",
      "    ^^^^^^^^^^^^^^^^^\n",
      "    ...<7 lines>...\n",
      "    ),\n",
      "    ^\n",
      "  File \"C:\\Dev\\Lang\\Python313\\Lib\\site-packages\\telegram\\_bot.py\", line 619, in _post\n",
      "    return await self._do_post(\n",
      "           ^^^^^^^^^^^^^^^^^^^^\n",
      "    ...<6 lines>...\n",
      "    )\n",
      "    ^\n",
      "  File \"C:\\Dev\\Lang\\Python313\\Lib\\site-packages\\telegram\\ext\\_extbot.py\", line 354, in _do_post\n",
      "    return await super()._do_post(\n",
      "           ^^^^^^^^^^^^^^^^^^^^^^^\n",
      "    ...<6 lines>...\n",
      "    )\n",
      "    ^\n",
      "  File \"C:\\Dev\\Lang\\Python313\\Lib\\site-packages\\telegram\\_bot.py\", line 648, in _do_post\n",
      "    result = await request.post(\n",
      "             ^^^^^^^^^^^^^^^^^^^\n",
      "    ...<6 lines>...\n",
      "    )\n",
      "    ^\n",
      "  File \"C:\\Dev\\Lang\\Python313\\Lib\\site-packages\\telegram\\request\\_baserequest.py\", line 202, in post\n",
      "    result = await self._request_wrapper(\n",
      "             ^^^^^^^^^^^^^^^^^^^^^^^^^^^^\n",
      "    ...<7 lines>...\n",
      "    )\n",
      "    ^\n",
      "  File \"C:\\Dev\\Lang\\Python313\\Lib\\site-packages\\telegram\\request\\_baserequest.py\", line 385, in _request_wrapper\n",
      "    raise Conflict(message)\n",
      "telegram.error.Conflict: Conflict: terminated by other getUpdates request; make sure that only one bot instance is running\n",
      "Exception happened while polling for updates.\n",
      "Traceback (most recent call last):\n",
      "  File \"C:\\Dev\\Lang\\Python313\\Lib\\site-packages\\telegram\\ext\\_updater.py\", line 750, in _network_loop_retry\n",
      "    if not await do_action():\n",
      "           ^^^^^^^^^^^^^^^^^\n",
      "  File \"C:\\Dev\\Lang\\Python313\\Lib\\site-packages\\telegram\\ext\\_updater.py\", line 744, in do_action\n",
      "    return action_cb_task.result()\n",
      "           ~~~~~~~~~~~~~~~~~~~~~^^\n",
      "  File \"C:\\Dev\\Lang\\Python313\\Lib\\asyncio\\futures.py\", line 199, in result\n",
      "    raise self._exception.with_traceback(self._exception_tb)\n",
      "  File \"C:\\Dev\\Lang\\Python313\\Lib\\asyncio\\tasks.py\", line 304, in __step_run_and_handle_result\n",
      "    result = coro.send(None)\n",
      "  File \"C:\\Dev\\Lang\\Python313\\Lib\\site-packages\\telegram\\ext\\_updater.py\", line 371, in polling_action_cb\n",
      "    updates = await self.bot.get_updates(\n",
      "              ^^^^^^^^^^^^^^^^^^^^^^^^^^^\n",
      "    ...<7 lines>...\n",
      "    )\n",
      "    ^\n",
      "  File \"C:\\Dev\\Lang\\Python313\\Lib\\site-packages\\telegram\\ext\\_extbot.py\", line 650, in get_updates\n",
      "    updates = await super().get_updates(\n",
      "              ^^^^^^^^^^^^^^^^^^^^^^^^^^\n",
      "    ...<9 lines>...\n",
      "    )\n",
      "    ^\n",
      "  File \"C:\\Dev\\Lang\\Python313\\Lib\\site-packages\\telegram\\_bot.py\", line 4480, in get_updates\n",
      "    await self._post(\n",
      "    ^^^^^^^^^^^^^^^^^\n",
      "    ...<7 lines>...\n",
      "    ),\n",
      "    ^\n",
      "  File \"C:\\Dev\\Lang\\Python313\\Lib\\site-packages\\telegram\\_bot.py\", line 619, in _post\n",
      "    return await self._do_post(\n",
      "           ^^^^^^^^^^^^^^^^^^^^\n",
      "    ...<6 lines>...\n",
      "    )\n",
      "    ^\n",
      "  File \"C:\\Dev\\Lang\\Python313\\Lib\\site-packages\\telegram\\ext\\_extbot.py\", line 354, in _do_post\n",
      "    return await super()._do_post(\n",
      "           ^^^^^^^^^^^^^^^^^^^^^^^\n",
      "    ...<6 lines>...\n",
      "    )\n",
      "    ^\n",
      "  File \"C:\\Dev\\Lang\\Python313\\Lib\\site-packages\\telegram\\_bot.py\", line 648, in _do_post\n",
      "    result = await request.post(\n",
      "             ^^^^^^^^^^^^^^^^^^^\n",
      "    ...<6 lines>...\n",
      "    )\n",
      "    ^\n",
      "  File \"C:\\Dev\\Lang\\Python313\\Lib\\site-packages\\telegram\\request\\_baserequest.py\", line 202, in post\n",
      "    result = await self._request_wrapper(\n",
      "             ^^^^^^^^^^^^^^^^^^^^^^^^^^^^\n",
      "    ...<7 lines>...\n",
      "    )\n",
      "    ^\n",
      "  File \"C:\\Dev\\Lang\\Python313\\Lib\\site-packages\\telegram\\request\\_baserequest.py\", line 385, in _request_wrapper\n",
      "    raise Conflict(message)\n",
      "telegram.error.Conflict: Conflict: terminated by other getUpdates request; make sure that only one bot instance is running\n",
      "Exception happened while polling for updates.\n",
      "Traceback (most recent call last):\n",
      "  File \"C:\\Dev\\Lang\\Python313\\Lib\\site-packages\\telegram\\ext\\_updater.py\", line 750, in _network_loop_retry\n",
      "    if not await do_action():\n",
      "           ^^^^^^^^^^^^^^^^^\n",
      "  File \"C:\\Dev\\Lang\\Python313\\Lib\\site-packages\\telegram\\ext\\_updater.py\", line 744, in do_action\n",
      "    return action_cb_task.result()\n",
      "           ~~~~~~~~~~~~~~~~~~~~~^^\n",
      "  File \"C:\\Dev\\Lang\\Python313\\Lib\\asyncio\\futures.py\", line 199, in result\n",
      "    raise self._exception.with_traceback(self._exception_tb)\n",
      "  File \"C:\\Dev\\Lang\\Python313\\Lib\\asyncio\\tasks.py\", line 304, in __step_run_and_handle_result\n",
      "    result = coro.send(None)\n",
      "  File \"C:\\Dev\\Lang\\Python313\\Lib\\site-packages\\telegram\\ext\\_updater.py\", line 371, in polling_action_cb\n",
      "    updates = await self.bot.get_updates(\n",
      "              ^^^^^^^^^^^^^^^^^^^^^^^^^^^\n",
      "    ...<7 lines>...\n",
      "    )\n",
      "    ^\n",
      "  File \"C:\\Dev\\Lang\\Python313\\Lib\\site-packages\\telegram\\ext\\_extbot.py\", line 650, in get_updates\n",
      "    updates = await super().get_updates(\n",
      "              ^^^^^^^^^^^^^^^^^^^^^^^^^^\n",
      "    ...<9 lines>...\n",
      "    )\n",
      "    ^\n",
      "  File \"C:\\Dev\\Lang\\Python313\\Lib\\site-packages\\telegram\\_bot.py\", line 4480, in get_updates\n",
      "    await self._post(\n",
      "    ^^^^^^^^^^^^^^^^^\n",
      "    ...<7 lines>...\n",
      "    ),\n",
      "    ^\n",
      "  File \"C:\\Dev\\Lang\\Python313\\Lib\\site-packages\\telegram\\_bot.py\", line 619, in _post\n",
      "    return await self._do_post(\n",
      "           ^^^^^^^^^^^^^^^^^^^^\n",
      "    ...<6 lines>...\n",
      "    )\n",
      "    ^\n",
      "  File \"C:\\Dev\\Lang\\Python313\\Lib\\site-packages\\telegram\\ext\\_extbot.py\", line 354, in _do_post\n",
      "    return await super()._do_post(\n",
      "           ^^^^^^^^^^^^^^^^^^^^^^^\n",
      "    ...<6 lines>...\n",
      "    )\n",
      "    ^\n",
      "  File \"C:\\Dev\\Lang\\Python313\\Lib\\site-packages\\telegram\\_bot.py\", line 648, in _do_post\n",
      "    result = await request.post(\n",
      "             ^^^^^^^^^^^^^^^^^^^\n",
      "    ...<6 lines>...\n",
      "    )\n",
      "    ^\n",
      "  File \"C:\\Dev\\Lang\\Python313\\Lib\\site-packages\\telegram\\request\\_baserequest.py\", line 202, in post\n",
      "    result = await self._request_wrapper(\n",
      "             ^^^^^^^^^^^^^^^^^^^^^^^^^^^^\n",
      "    ...<7 lines>...\n",
      "    )\n",
      "    ^\n",
      "  File \"C:\\Dev\\Lang\\Python313\\Lib\\site-packages\\telegram\\request\\_baserequest.py\", line 385, in _request_wrapper\n",
      "    raise Conflict(message)\n",
      "telegram.error.Conflict: Conflict: terminated by other getUpdates request; make sure that only one bot instance is running\n",
      "Exception happened while polling for updates.\n",
      "Traceback (most recent call last):\n",
      "  File \"C:\\Dev\\Lang\\Python313\\Lib\\site-packages\\telegram\\ext\\_updater.py\", line 750, in _network_loop_retry\n",
      "    if not await do_action():\n",
      "           ^^^^^^^^^^^^^^^^^\n",
      "  File \"C:\\Dev\\Lang\\Python313\\Lib\\site-packages\\telegram\\ext\\_updater.py\", line 744, in do_action\n",
      "    return action_cb_task.result()\n",
      "           ~~~~~~~~~~~~~~~~~~~~~^^\n",
      "  File \"C:\\Dev\\Lang\\Python313\\Lib\\asyncio\\futures.py\", line 199, in result\n",
      "    raise self._exception.with_traceback(self._exception_tb)\n",
      "  File \"C:\\Dev\\Lang\\Python313\\Lib\\asyncio\\tasks.py\", line 304, in __step_run_and_handle_result\n",
      "    result = coro.send(None)\n",
      "  File \"C:\\Dev\\Lang\\Python313\\Lib\\site-packages\\telegram\\ext\\_updater.py\", line 371, in polling_action_cb\n",
      "    updates = await self.bot.get_updates(\n",
      "              ^^^^^^^^^^^^^^^^^^^^^^^^^^^\n",
      "    ...<7 lines>...\n",
      "    )\n",
      "    ^\n",
      "  File \"C:\\Dev\\Lang\\Python313\\Lib\\site-packages\\telegram\\ext\\_extbot.py\", line 650, in get_updates\n",
      "    updates = await super().get_updates(\n",
      "              ^^^^^^^^^^^^^^^^^^^^^^^^^^\n",
      "    ...<9 lines>...\n",
      "    )\n",
      "    ^\n",
      "  File \"C:\\Dev\\Lang\\Python313\\Lib\\site-packages\\telegram\\_bot.py\", line 4480, in get_updates\n",
      "    await self._post(\n",
      "    ^^^^^^^^^^^^^^^^^\n",
      "    ...<7 lines>...\n",
      "    ),\n",
      "    ^\n",
      "  File \"C:\\Dev\\Lang\\Python313\\Lib\\site-packages\\telegram\\_bot.py\", line 619, in _post\n",
      "    return await self._do_post(\n",
      "           ^^^^^^^^^^^^^^^^^^^^\n",
      "    ...<6 lines>...\n",
      "    )\n",
      "    ^\n",
      "  File \"C:\\Dev\\Lang\\Python313\\Lib\\site-packages\\telegram\\ext\\_extbot.py\", line 354, in _do_post\n",
      "    return await super()._do_post(\n",
      "           ^^^^^^^^^^^^^^^^^^^^^^^\n",
      "    ...<6 lines>...\n",
      "    )\n",
      "    ^\n",
      "  File \"C:\\Dev\\Lang\\Python313\\Lib\\site-packages\\telegram\\_bot.py\", line 648, in _do_post\n",
      "    result = await request.post(\n",
      "             ^^^^^^^^^^^^^^^^^^^\n",
      "    ...<6 lines>...\n",
      "    )\n",
      "    ^\n",
      "  File \"C:\\Dev\\Lang\\Python313\\Lib\\site-packages\\telegram\\request\\_baserequest.py\", line 202, in post\n",
      "    result = await self._request_wrapper(\n",
      "             ^^^^^^^^^^^^^^^^^^^^^^^^^^^^\n",
      "    ...<7 lines>...\n",
      "    )\n",
      "    ^\n",
      "  File \"C:\\Dev\\Lang\\Python313\\Lib\\site-packages\\telegram\\request\\_baserequest.py\", line 385, in _request_wrapper\n",
      "    raise Conflict(message)\n",
      "telegram.error.Conflict: Conflict: terminated by other getUpdates request; make sure that only one bot instance is running\n",
      "Exception happened while polling for updates.\n",
      "Traceback (most recent call last):\n",
      "  File \"C:\\Dev\\Lang\\Python313\\Lib\\site-packages\\telegram\\ext\\_updater.py\", line 750, in _network_loop_retry\n",
      "    if not await do_action():\n",
      "           ^^^^^^^^^^^^^^^^^\n",
      "  File \"C:\\Dev\\Lang\\Python313\\Lib\\site-packages\\telegram\\ext\\_updater.py\", line 744, in do_action\n",
      "    return action_cb_task.result()\n",
      "           ~~~~~~~~~~~~~~~~~~~~~^^\n",
      "  File \"C:\\Dev\\Lang\\Python313\\Lib\\asyncio\\futures.py\", line 199, in result\n",
      "    raise self._exception.with_traceback(self._exception_tb)\n",
      "  File \"C:\\Dev\\Lang\\Python313\\Lib\\asyncio\\tasks.py\", line 304, in __step_run_and_handle_result\n",
      "    result = coro.send(None)\n",
      "  File \"C:\\Dev\\Lang\\Python313\\Lib\\site-packages\\telegram\\ext\\_updater.py\", line 371, in polling_action_cb\n",
      "    updates = await self.bot.get_updates(\n",
      "              ^^^^^^^^^^^^^^^^^^^^^^^^^^^\n",
      "    ...<7 lines>...\n",
      "    )\n",
      "    ^\n",
      "  File \"C:\\Dev\\Lang\\Python313\\Lib\\site-packages\\telegram\\ext\\_extbot.py\", line 650, in get_updates\n",
      "    updates = await super().get_updates(\n",
      "              ^^^^^^^^^^^^^^^^^^^^^^^^^^\n",
      "    ...<9 lines>...\n",
      "    )\n",
      "    ^\n",
      "  File \"C:\\Dev\\Lang\\Python313\\Lib\\site-packages\\telegram\\_bot.py\", line 4480, in get_updates\n",
      "    await self._post(\n",
      "    ^^^^^^^^^^^^^^^^^\n",
      "    ...<7 lines>...\n",
      "    ),\n",
      "    ^\n",
      "  File \"C:\\Dev\\Lang\\Python313\\Lib\\site-packages\\telegram\\_bot.py\", line 619, in _post\n",
      "    return await self._do_post(\n",
      "           ^^^^^^^^^^^^^^^^^^^^\n",
      "    ...<6 lines>...\n",
      "    )\n",
      "    ^\n",
      "  File \"C:\\Dev\\Lang\\Python313\\Lib\\site-packages\\telegram\\ext\\_extbot.py\", line 354, in _do_post\n",
      "    return await super()._do_post(\n",
      "           ^^^^^^^^^^^^^^^^^^^^^^^\n",
      "    ...<6 lines>...\n",
      "    )\n",
      "    ^\n",
      "  File \"C:\\Dev\\Lang\\Python313\\Lib\\site-packages\\telegram\\_bot.py\", line 648, in _do_post\n",
      "    result = await request.post(\n",
      "             ^^^^^^^^^^^^^^^^^^^\n",
      "    ...<6 lines>...\n",
      "    )\n",
      "    ^\n",
      "  File \"C:\\Dev\\Lang\\Python313\\Lib\\site-packages\\telegram\\request\\_baserequest.py\", line 202, in post\n",
      "    result = await self._request_wrapper(\n",
      "             ^^^^^^^^^^^^^^^^^^^^^^^^^^^^\n",
      "    ...<7 lines>...\n",
      "    )\n",
      "    ^\n",
      "  File \"C:\\Dev\\Lang\\Python313\\Lib\\site-packages\\telegram\\request\\_baserequest.py\", line 385, in _request_wrapper\n",
      "    raise Conflict(message)\n",
      "telegram.error.Conflict: Conflict: terminated by other getUpdates request; make sure that only one bot instance is running\n",
      "Exception happened while polling for updates.\n",
      "Traceback (most recent call last):\n",
      "  File \"C:\\Dev\\Lang\\Python313\\Lib\\site-packages\\telegram\\ext\\_updater.py\", line 750, in _network_loop_retry\n",
      "    if not await do_action():\n",
      "           ^^^^^^^^^^^^^^^^^\n",
      "  File \"C:\\Dev\\Lang\\Python313\\Lib\\site-packages\\telegram\\ext\\_updater.py\", line 744, in do_action\n",
      "    return action_cb_task.result()\n",
      "           ~~~~~~~~~~~~~~~~~~~~~^^\n",
      "  File \"C:\\Dev\\Lang\\Python313\\Lib\\asyncio\\futures.py\", line 199, in result\n",
      "    raise self._exception.with_traceback(self._exception_tb)\n",
      "  File \"C:\\Dev\\Lang\\Python313\\Lib\\asyncio\\tasks.py\", line 304, in __step_run_and_handle_result\n",
      "    result = coro.send(None)\n",
      "  File \"C:\\Dev\\Lang\\Python313\\Lib\\site-packages\\telegram\\ext\\_updater.py\", line 371, in polling_action_cb\n",
      "    updates = await self.bot.get_updates(\n",
      "              ^^^^^^^^^^^^^^^^^^^^^^^^^^^\n",
      "    ...<7 lines>...\n",
      "    )\n",
      "    ^\n",
      "  File \"C:\\Dev\\Lang\\Python313\\Lib\\site-packages\\telegram\\ext\\_extbot.py\", line 650, in get_updates\n",
      "    updates = await super().get_updates(\n",
      "              ^^^^^^^^^^^^^^^^^^^^^^^^^^\n",
      "    ...<9 lines>...\n",
      "    )\n",
      "    ^\n",
      "  File \"C:\\Dev\\Lang\\Python313\\Lib\\site-packages\\telegram\\_bot.py\", line 4480, in get_updates\n",
      "    await self._post(\n",
      "    ^^^^^^^^^^^^^^^^^\n",
      "    ...<7 lines>...\n",
      "    ),\n",
      "    ^\n",
      "  File \"C:\\Dev\\Lang\\Python313\\Lib\\site-packages\\telegram\\_bot.py\", line 619, in _post\n",
      "    return await self._do_post(\n",
      "           ^^^^^^^^^^^^^^^^^^^^\n",
      "    ...<6 lines>...\n",
      "    )\n",
      "    ^\n",
      "  File \"C:\\Dev\\Lang\\Python313\\Lib\\site-packages\\telegram\\ext\\_extbot.py\", line 354, in _do_post\n",
      "    return await super()._do_post(\n",
      "           ^^^^^^^^^^^^^^^^^^^^^^^\n",
      "    ...<6 lines>...\n",
      "    )\n",
      "    ^\n",
      "  File \"C:\\Dev\\Lang\\Python313\\Lib\\site-packages\\telegram\\_bot.py\", line 648, in _do_post\n",
      "    result = await request.post(\n",
      "             ^^^^^^^^^^^^^^^^^^^\n",
      "    ...<6 lines>...\n",
      "    )\n",
      "    ^\n",
      "  File \"C:\\Dev\\Lang\\Python313\\Lib\\site-packages\\telegram\\request\\_baserequest.py\", line 202, in post\n",
      "    result = await self._request_wrapper(\n",
      "             ^^^^^^^^^^^^^^^^^^^^^^^^^^^^\n",
      "    ...<7 lines>...\n",
      "    )\n",
      "    ^\n",
      "  File \"C:\\Dev\\Lang\\Python313\\Lib\\site-packages\\telegram\\request\\_baserequest.py\", line 385, in _request_wrapper\n",
      "    raise Conflict(message)\n",
      "telegram.error.Conflict: Conflict: terminated by other getUpdates request; make sure that only one bot instance is running\n",
      "Exception happened while polling for updates.\n",
      "Traceback (most recent call last):\n",
      "  File \"C:\\Dev\\Lang\\Python313\\Lib\\site-packages\\telegram\\ext\\_updater.py\", line 750, in _network_loop_retry\n",
      "    if not await do_action():\n",
      "           ^^^^^^^^^^^^^^^^^\n",
      "  File \"C:\\Dev\\Lang\\Python313\\Lib\\site-packages\\telegram\\ext\\_updater.py\", line 744, in do_action\n",
      "    return action_cb_task.result()\n",
      "           ~~~~~~~~~~~~~~~~~~~~~^^\n",
      "  File \"C:\\Dev\\Lang\\Python313\\Lib\\asyncio\\futures.py\", line 199, in result\n",
      "    raise self._exception.with_traceback(self._exception_tb)\n",
      "  File \"C:\\Dev\\Lang\\Python313\\Lib\\asyncio\\tasks.py\", line 304, in __step_run_and_handle_result\n",
      "    result = coro.send(None)\n",
      "  File \"C:\\Dev\\Lang\\Python313\\Lib\\site-packages\\telegram\\ext\\_updater.py\", line 371, in polling_action_cb\n",
      "    updates = await self.bot.get_updates(\n",
      "              ^^^^^^^^^^^^^^^^^^^^^^^^^^^\n",
      "    ...<7 lines>...\n",
      "    )\n",
      "    ^\n",
      "  File \"C:\\Dev\\Lang\\Python313\\Lib\\site-packages\\telegram\\ext\\_extbot.py\", line 650, in get_updates\n",
      "    updates = await super().get_updates(\n",
      "              ^^^^^^^^^^^^^^^^^^^^^^^^^^\n",
      "    ...<9 lines>...\n",
      "    )\n",
      "    ^\n",
      "  File \"C:\\Dev\\Lang\\Python313\\Lib\\site-packages\\telegram\\_bot.py\", line 4480, in get_updates\n",
      "    await self._post(\n",
      "    ^^^^^^^^^^^^^^^^^\n",
      "    ...<7 lines>...\n",
      "    ),\n",
      "    ^\n",
      "  File \"C:\\Dev\\Lang\\Python313\\Lib\\site-packages\\telegram\\_bot.py\", line 619, in _post\n",
      "    return await self._do_post(\n",
      "           ^^^^^^^^^^^^^^^^^^^^\n",
      "    ...<6 lines>...\n",
      "    )\n",
      "    ^\n",
      "  File \"C:\\Dev\\Lang\\Python313\\Lib\\site-packages\\telegram\\ext\\_extbot.py\", line 354, in _do_post\n",
      "    return await super()._do_post(\n",
      "           ^^^^^^^^^^^^^^^^^^^^^^^\n",
      "    ...<6 lines>...\n",
      "    )\n",
      "    ^\n",
      "  File \"C:\\Dev\\Lang\\Python313\\Lib\\site-packages\\telegram\\_bot.py\", line 648, in _do_post\n",
      "    result = await request.post(\n",
      "             ^^^^^^^^^^^^^^^^^^^\n",
      "    ...<6 lines>...\n",
      "    )\n",
      "    ^\n",
      "  File \"C:\\Dev\\Lang\\Python313\\Lib\\site-packages\\telegram\\request\\_baserequest.py\", line 202, in post\n",
      "    result = await self._request_wrapper(\n",
      "             ^^^^^^^^^^^^^^^^^^^^^^^^^^^^\n",
      "    ...<7 lines>...\n",
      "    )\n",
      "    ^\n",
      "  File \"C:\\Dev\\Lang\\Python313\\Lib\\site-packages\\telegram\\request\\_baserequest.py\", line 385, in _request_wrapper\n",
      "    raise Conflict(message)\n",
      "telegram.error.Conflict: Conflict: terminated by other getUpdates request; make sure that only one bot instance is running\n",
      "Exception happened while polling for updates.\n",
      "Traceback (most recent call last):\n",
      "  File \"C:\\Dev\\Lang\\Python313\\Lib\\site-packages\\telegram\\ext\\_updater.py\", line 750, in _network_loop_retry\n",
      "    if not await do_action():\n",
      "           ^^^^^^^^^^^^^^^^^\n",
      "  File \"C:\\Dev\\Lang\\Python313\\Lib\\site-packages\\telegram\\ext\\_updater.py\", line 744, in do_action\n",
      "    return action_cb_task.result()\n",
      "           ~~~~~~~~~~~~~~~~~~~~~^^\n",
      "  File \"C:\\Dev\\Lang\\Python313\\Lib\\asyncio\\futures.py\", line 199, in result\n",
      "    raise self._exception.with_traceback(self._exception_tb)\n",
      "  File \"C:\\Dev\\Lang\\Python313\\Lib\\asyncio\\tasks.py\", line 304, in __step_run_and_handle_result\n",
      "    result = coro.send(None)\n",
      "  File \"C:\\Dev\\Lang\\Python313\\Lib\\site-packages\\telegram\\ext\\_updater.py\", line 371, in polling_action_cb\n",
      "    updates = await self.bot.get_updates(\n",
      "              ^^^^^^^^^^^^^^^^^^^^^^^^^^^\n",
      "    ...<7 lines>...\n",
      "    )\n",
      "    ^\n",
      "  File \"C:\\Dev\\Lang\\Python313\\Lib\\site-packages\\telegram\\ext\\_extbot.py\", line 650, in get_updates\n",
      "    updates = await super().get_updates(\n",
      "              ^^^^^^^^^^^^^^^^^^^^^^^^^^\n",
      "    ...<9 lines>...\n",
      "    )\n",
      "    ^\n",
      "  File \"C:\\Dev\\Lang\\Python313\\Lib\\site-packages\\telegram\\_bot.py\", line 4480, in get_updates\n",
      "    await self._post(\n",
      "    ^^^^^^^^^^^^^^^^^\n",
      "    ...<7 lines>...\n",
      "    ),\n",
      "    ^\n",
      "  File \"C:\\Dev\\Lang\\Python313\\Lib\\site-packages\\telegram\\_bot.py\", line 619, in _post\n",
      "    return await self._do_post(\n",
      "           ^^^^^^^^^^^^^^^^^^^^\n",
      "    ...<6 lines>...\n",
      "    )\n",
      "    ^\n",
      "  File \"C:\\Dev\\Lang\\Python313\\Lib\\site-packages\\telegram\\ext\\_extbot.py\", line 354, in _do_post\n",
      "    return await super()._do_post(\n",
      "           ^^^^^^^^^^^^^^^^^^^^^^^\n",
      "    ...<6 lines>...\n",
      "    )\n",
      "    ^\n",
      "  File \"C:\\Dev\\Lang\\Python313\\Lib\\site-packages\\telegram\\_bot.py\", line 648, in _do_post\n",
      "    result = await request.post(\n",
      "             ^^^^^^^^^^^^^^^^^^^\n",
      "    ...<6 lines>...\n",
      "    )\n",
      "    ^\n",
      "  File \"C:\\Dev\\Lang\\Python313\\Lib\\site-packages\\telegram\\request\\_baserequest.py\", line 202, in post\n",
      "    result = await self._request_wrapper(\n",
      "             ^^^^^^^^^^^^^^^^^^^^^^^^^^^^\n",
      "    ...<7 lines>...\n",
      "    )\n",
      "    ^\n",
      "  File \"C:\\Dev\\Lang\\Python313\\Lib\\site-packages\\telegram\\request\\_baserequest.py\", line 385, in _request_wrapper\n",
      "    raise Conflict(message)\n",
      "telegram.error.Conflict: Conflict: terminated by other getUpdates request; make sure that only one bot instance is running\n",
      "Exception happened while polling for updates.\n",
      "Traceback (most recent call last):\n",
      "  File \"C:\\Dev\\Lang\\Python313\\Lib\\site-packages\\telegram\\ext\\_updater.py\", line 750, in _network_loop_retry\n",
      "    if not await do_action():\n",
      "           ^^^^^^^^^^^^^^^^^\n",
      "  File \"C:\\Dev\\Lang\\Python313\\Lib\\site-packages\\telegram\\ext\\_updater.py\", line 744, in do_action\n",
      "    return action_cb_task.result()\n",
      "           ~~~~~~~~~~~~~~~~~~~~~^^\n",
      "  File \"C:\\Dev\\Lang\\Python313\\Lib\\asyncio\\futures.py\", line 199, in result\n",
      "    raise self._exception.with_traceback(self._exception_tb)\n",
      "  File \"C:\\Dev\\Lang\\Python313\\Lib\\asyncio\\tasks.py\", line 304, in __step_run_and_handle_result\n",
      "    result = coro.send(None)\n",
      "  File \"C:\\Dev\\Lang\\Python313\\Lib\\site-packages\\telegram\\ext\\_updater.py\", line 371, in polling_action_cb\n",
      "    updates = await self.bot.get_updates(\n",
      "              ^^^^^^^^^^^^^^^^^^^^^^^^^^^\n",
      "    ...<7 lines>...\n",
      "    )\n",
      "    ^\n",
      "  File \"C:\\Dev\\Lang\\Python313\\Lib\\site-packages\\telegram\\ext\\_extbot.py\", line 650, in get_updates\n",
      "    updates = await super().get_updates(\n",
      "              ^^^^^^^^^^^^^^^^^^^^^^^^^^\n",
      "    ...<9 lines>...\n",
      "    )\n",
      "    ^\n",
      "  File \"C:\\Dev\\Lang\\Python313\\Lib\\site-packages\\telegram\\_bot.py\", line 4480, in get_updates\n",
      "    await self._post(\n",
      "    ^^^^^^^^^^^^^^^^^\n",
      "    ...<7 lines>...\n",
      "    ),\n",
      "    ^\n",
      "  File \"C:\\Dev\\Lang\\Python313\\Lib\\site-packages\\telegram\\_bot.py\", line 619, in _post\n",
      "    return await self._do_post(\n",
      "           ^^^^^^^^^^^^^^^^^^^^\n",
      "    ...<6 lines>...\n",
      "    )\n",
      "    ^\n",
      "  File \"C:\\Dev\\Lang\\Python313\\Lib\\site-packages\\telegram\\ext\\_extbot.py\", line 354, in _do_post\n",
      "    return await super()._do_post(\n",
      "           ^^^^^^^^^^^^^^^^^^^^^^^\n",
      "    ...<6 lines>...\n",
      "    )\n",
      "    ^\n",
      "  File \"C:\\Dev\\Lang\\Python313\\Lib\\site-packages\\telegram\\_bot.py\", line 648, in _do_post\n",
      "    result = await request.post(\n",
      "             ^^^^^^^^^^^^^^^^^^^\n",
      "    ...<6 lines>...\n",
      "    )\n",
      "    ^\n",
      "  File \"C:\\Dev\\Lang\\Python313\\Lib\\site-packages\\telegram\\request\\_baserequest.py\", line 202, in post\n",
      "    result = await self._request_wrapper(\n",
      "             ^^^^^^^^^^^^^^^^^^^^^^^^^^^^\n",
      "    ...<7 lines>...\n",
      "    )\n",
      "    ^\n",
      "  File \"C:\\Dev\\Lang\\Python313\\Lib\\site-packages\\telegram\\request\\_baserequest.py\", line 385, in _request_wrapper\n",
      "    raise Conflict(message)\n",
      "telegram.error.Conflict: Conflict: terminated by other getUpdates request; make sure that only one bot instance is running\n"
     ]
    }
   ],
   "source": [
    "import asyncio\n",
    "import nest_asyncio # 주피터랩용\n",
    "from dotenv import load_dotenv\n",
    "import os\n",
    "#.env 업로드\n",
    "load_dotenv()\n",
    "from telegram import Update\n",
    "from telegram.ext import Application, CommandHandler, MessageHandler, filters, CallbackContext\n",
    "nest_asyncio.apply()\n",
    "\n",
    "TELEGRAM_TOKEN =os.getenv(\"TELEGRAM_TOKEN\")\n",
    "\n",
    "async def start( update, context):\n",
    "    await context.bot.send_message(chat_id=update.effective_chat.id, text=\"봇이 가동되었습니다!\")\n",
    "\n",
    "async def handle_message(update , context ):\n",
    "    user_message = update.message.text.lower()  # Text -> text\n",
    "\n",
    "    if \"안녕\" in user_message:\n",
    "        response = \"안녕하세요!\"\n",
    "    elif \"날씨\" in user_message:\n",
    "        response = \"이번주는 계속 추울 것 같아요ㅜㅠ 다음주부터 따뜻해진대요!\"\n",
    "    elif \"배고\" in user_message:\n",
    "        response = \"ㅜㅠ 어뜩하져 안타깝지만 좀만 더 참으세요\"\n",
    "    elif \"심심\" in user_message:\n",
    "        response = \"심심하시다구여?? 머하구 놀아드릴까요!!\"\n",
    "    elif \"고민\" in user_message:\n",
    "        response = \"저한테 말씀해보세요! 제가 해결해드릴 순 없겠지만 말하다보면 고민이 해결될 수도 있어요. 뭐든 들어드릴게요\"\n",
    "    elif \"혜빈\" in user_message:\n",
    "        response = \"그게 누구죠? 사람은 맞나요?\"\n",
    "    elif \"저녁 추천\" in user_message:\n",
    "        response = \"고민될 땐 치킨이죠!\"\n",
    "    print(response)\n",
    "\n",
    "    #응답 메세지 전송\n",
    "    await context.bot.send_message(chat_id=update.effective_chat.id, text=response)\n",
    "\n",
    "async def main():\n",
    "    application = Application.builder().token(TELEGRAM_TOKEN).build()\n",
    "    await application.initialize() # 초기화 필수\n",
    "\n",
    "    # 핸들러 추가\n",
    "    application.add_handler(CommandHandler(\"start\", start))\n",
    "    application.add_handler(MessageHandler(filters.TEXT & ~filters.COMMAND, handle_message))\n",
    "    \n",
    "    await application.start()\n",
    "    print(\"봇이 실행중 입니다.\")\n",
    "\n",
    "    await application.updater.start_polling()\n",
    "\n",
    "if __name__ == \"__main__\":\n",
    "    asyncio.run(main())"
   ]
  },
  {
   "cell_type": "code",
   "execution_count": null,
   "id": "414e728f-a461-4b94-84a2-a66c67c5e548",
   "metadata": {},
   "outputs": [],
   "source": []
  }
 ],
 "metadata": {
  "kernelspec": {
   "display_name": "Python 3 (ipykernel)",
   "language": "python",
   "name": "python3"
  },
  "language_info": {
   "codemirror_mode": {
    "name": "ipython",
    "version": 3
   },
   "file_extension": ".py",
   "mimetype": "text/x-python",
   "name": "python",
   "nbconvert_exporter": "python",
   "pygments_lexer": "ipython3",
   "version": "3.13.1"
  }
 },
 "nbformat": 4,
 "nbformat_minor": 5
}
